2022-06-22 13:26:37,401 DEBUG    root            Loaded Command Group: ['gcloud', 'config']
2022-06-22 13:26:37,402 DEBUG    root            Loaded Command Group: ['gcloud', 'config', 'config_helper']
2022-06-22 13:26:37,403 DEBUG    root            Running [gcloud.config.config-helper] with arguments: [--format: "json"]
2022-06-22 13:26:37,405 DEBUG    google.auth.transport.requests Making request: POST https://oauth2.googleapis.com/token
2022-06-22 13:26:37,411 DEBUG    urllib3.connectionpool Starting new HTTPS connection (1): oauth2.googleapis.com:443
2022-06-22 13:26:37,485 DEBUG    google.auth.transport.requests Making request: POST https://oauth2.googleapis.com/token
2022-06-22 13:26:37,488 DEBUG    urllib3.connectionpool Starting new HTTPS connection (2): oauth2.googleapis.com:443
2022-06-22 13:26:37,558 DEBUG    root            HTTPSConnectionPool(host='oauth2.googleapis.com', port=443): Max retries exceeded with url: /token (Caused by SSLError(SSLCertVerificationError(1, '[SSL: CERTIFICATE_VERIFY_FAILED] certificate verify failed: unable to get local issuer certificate (_ssl.c:1129)')))
Traceback (most recent call last):
  File "/opt/homebrew/Caskroom/google-cloud-sdk/latest/google-cloud-sdk/lib/third_party/urllib3/connectionpool.py", line 667, in urlopen
    self._prepare_proxy(conn)
  File "/opt/homebrew/Caskroom/google-cloud-sdk/latest/google-cloud-sdk/lib/third_party/urllib3/connectionpool.py", line 930, in _prepare_proxy
    conn.connect()
  File "/opt/homebrew/Caskroom/google-cloud-sdk/latest/google-cloud-sdk/lib/third_party/urllib3/connection.py", line 361, in connect
    self.sock = ssl_wrap_socket(
  File "/opt/homebrew/Caskroom/google-cloud-sdk/latest/google-cloud-sdk/lib/third_party/urllib3/util/ssl_.py", line 382, in ssl_wrap_socket
    return context.wrap_socket(sock, server_hostname=server_hostname)
  File "/opt/homebrew/Cellar/python@3.9/3.9.13_1/Frameworks/Python.framework/Versions/3.9/lib/python3.9/ssl.py", line 501, in wrap_socket
    return self.sslsocket_class._create(
  File "/opt/homebrew/Cellar/python@3.9/3.9.13_1/Frameworks/Python.framework/Versions/3.9/lib/python3.9/ssl.py", line 1041, in _create
    self.do_handshake()
  File "/opt/homebrew/Cellar/python@3.9/3.9.13_1/Frameworks/Python.framework/Versions/3.9/lib/python3.9/ssl.py", line 1310, in do_handshake
    self._sslobj.do_handshake()
ssl.SSLCertVerificationError: [SSL: CERTIFICATE_VERIFY_FAILED] certificate verify failed: unable to get local issuer certificate (_ssl.c:1129)

During handling of the above exception, another exception occurred:

Traceback (most recent call last):
  File "/opt/homebrew/Caskroom/google-cloud-sdk/latest/google-cloud-sdk/lib/third_party/requests/adapters.py", line 439, in send
    resp = conn.urlopen(
  File "/opt/homebrew/Caskroom/google-cloud-sdk/latest/google-cloud-sdk/lib/third_party/urllib3/connectionpool.py", line 724, in urlopen
    retries = retries.increment(
  File "/opt/homebrew/Caskroom/google-cloud-sdk/latest/google-cloud-sdk/lib/third_party/urllib3/util/retry.py", line 439, in increment
    raise MaxRetryError(_pool, url, error or ResponseError(cause))
urllib3.exceptions.MaxRetryError: HTTPSConnectionPool(host='oauth2.googleapis.com', port=443): Max retries exceeded with url: /token (Caused by SSLError(SSLCertVerificationError(1, '[SSL: CERTIFICATE_VERIFY_FAILED] certificate verify failed: unable to get local issuer certificate (_ssl.c:1129)')))

During handling of the above exception, another exception occurred:

Traceback (most recent call last):
  File "/opt/homebrew/Caskroom/google-cloud-sdk/latest/google-cloud-sdk/lib/third_party/google/auth/transport/requests.py", line 183, in __call__
    response = self.session.request(
  File "/opt/homebrew/Caskroom/google-cloud-sdk/latest/google-cloud-sdk/lib/googlecloudsdk/core/transport.py", line 251, in WrappedRequest
    response = orig_request(*modified_args, **modified_kwargs)
  File "/opt/homebrew/Caskroom/google-cloud-sdk/latest/google-cloud-sdk/lib/googlecloudsdk/core/requests.py", line 216, in WrappedRequest
    return orig_request_method(*args, **kwargs)
  File "/opt/homebrew/Caskroom/google-cloud-sdk/latest/google-cloud-sdk/lib/third_party/requests/sessions.py", line 533, in request
    resp = self.send(prep, **send_kwargs)
  File "/opt/homebrew/Caskroom/google-cloud-sdk/latest/google-cloud-sdk/lib/third_party/requests/sessions.py", line 646, in send
    r = adapter.send(request, **kwargs)
  File "/opt/homebrew/Caskroom/google-cloud-sdk/latest/google-cloud-sdk/lib/third_party/requests/adapters.py", line 514, in send
    raise SSLError(e, request=request)
requests.exceptions.SSLError: HTTPSConnectionPool(host='oauth2.googleapis.com', port=443): Max retries exceeded with url: /token (Caused by SSLError(SSLCertVerificationError(1, '[SSL: CERTIFICATE_VERIFY_FAILED] certificate verify failed: unable to get local issuer certificate (_ssl.c:1129)')))

The above exception was the direct cause of the following exception:

Traceback (most recent call last):
  File "/opt/homebrew/Caskroom/google-cloud-sdk/latest/google-cloud-sdk/lib/googlecloudsdk/calliope/cli.py", line 987, in Execute
    resources = calliope_command.Run(cli=self, args=args)
  File "/opt/homebrew/Caskroom/google-cloud-sdk/latest/google-cloud-sdk/lib/googlecloudsdk/calliope/backend.py", line 809, in Run
    resources = command_instance.Run(args)
  File "/opt/homebrew/Caskroom/google-cloud-sdk/latest/google-cloud-sdk/lib/surface/config/config_helper.py", line 99, in Run
    cred = store.Load(use_google_auth=True)
  File "/opt/homebrew/Caskroom/google-cloud-sdk/latest/google-cloud-sdk/lib/googlecloudsdk/core/credentials/store.py", line 565, in Load
    cred = _Load(
  File "/opt/homebrew/Caskroom/google-cloud-sdk/latest/google-cloud-sdk/lib/googlecloudsdk/core/credentials/store.py", line 728, in _Load
    RefreshIfAlmostExpire(cred)
  File "/opt/homebrew/Caskroom/google-cloud-sdk/latest/google-cloud-sdk/lib/googlecloudsdk/core/credentials/store.py", line 942, in RefreshIfAlmostExpire
    RefreshIfExpireWithinWindow(credentials, window=_CREDENTIALS_EXPIRY_WINDOW)
  File "/opt/homebrew/Caskroom/google-cloud-sdk/latest/google-cloud-sdk/lib/googlecloudsdk/core/credentials/store.py", line 938, in RefreshIfExpireWithinWindow
    Refresh(credentials)
  File "/opt/homebrew/Caskroom/google-cloud-sdk/latest/google-cloud-sdk/lib/googlecloudsdk/core/credentials/store.py", line 772, in Refresh
    _RefreshGoogleAuth(credentials, http_client, is_impersonated_credential,
  File "/opt/homebrew/Caskroom/google-cloud-sdk/latest/google-cloud-sdk/lib/googlecloudsdk/core/credentials/store.py", line 882, in _RefreshGoogleAuth
    credentials.refresh(request_client)
  File "/opt/homebrew/Caskroom/google-cloud-sdk/latest/google-cloud-sdk/lib/googlecloudsdk/core/credentials/creds.py", line 553, in _WrappedRefresh
    orig_refresh(request)
  File "/opt/homebrew/Caskroom/google-cloud-sdk/latest/google-cloud-sdk/lib/googlecloudsdk/core/credentials/google_auth_credentials.py", line 102, in refresh
    return self._Refresh(request)
  File "/opt/homebrew/Caskroom/google-cloud-sdk/latest/google-cloud-sdk/lib/googlecloudsdk/core/credentials/google_auth_credentials.py", line 129, in _Refresh
    access_token, refresh_token, expiry, grant_response = _RefreshGrant(
  File "/opt/homebrew/Caskroom/google-cloud-sdk/latest/google-cloud-sdk/lib/googlecloudsdk/core/credentials/google_auth_credentials.py", line 206, in _RefreshGrant
    response_data = _TokenEndpointRequestWithRetry(request, token_uri, body)
  File "/opt/homebrew/Caskroom/google-cloud-sdk/latest/google-cloud-sdk/lib/googlecloudsdk/core/util/retry.py", line 312, in DecoratedFunction
    exceptions.reraise(to_reraise[1], tb=to_reraise[2])
  File "/opt/homebrew/Caskroom/google-cloud-sdk/latest/google-cloud-sdk/lib/googlecloudsdk/core/exceptions.py", line 146, in reraise
    six.reraise(type(exc_value), exc_value, tb)
  File "/opt/homebrew/Caskroom/google-cloud-sdk/latest/google-cloud-sdk/lib/third_party/six/__init__.py", line 693, in reraise
    raise value
  File "/opt/homebrew/Caskroom/google-cloud-sdk/latest/google-cloud-sdk/lib/googlecloudsdk/core/util/retry.py", line 182, in TryFunc
    return func(*args, **kwargs), None
  File "/opt/homebrew/Caskroom/google-cloud-sdk/latest/google-cloud-sdk/lib/googlecloudsdk/core/credentials/google_auth_credentials.py", line 262, in _TokenEndpointRequestWithRetry
    response = request(method='POST', url=token_uri, headers=headers, body=body)
  File "/opt/homebrew/Caskroom/google-cloud-sdk/latest/google-cloud-sdk/lib/third_party/google/auth/transport/requests.py", line 189, in __call__
    six.raise_from(new_exc, caught_exc)
  File "<string>", line 3, in raise_from
google.auth.exceptions.TransportError: HTTPSConnectionPool(host='oauth2.googleapis.com', port=443): Max retries exceeded with url: /token (Caused by SSLError(SSLCertVerificationError(1, '[SSL: CERTIFICATE_VERIFY_FAILED] certificate verify failed: unable to get local issuer certificate (_ssl.c:1129)')))
2022-06-22 13:26:37,561 ERROR    ___FILE_ONLY___ BEGIN CRASH STACKTRACE
Traceback (most recent call last):
  File "/opt/homebrew/Caskroom/google-cloud-sdk/latest/google-cloud-sdk/lib/third_party/urllib3/connectionpool.py", line 667, in urlopen
    self._prepare_proxy(conn)
  File "/opt/homebrew/Caskroom/google-cloud-sdk/latest/google-cloud-sdk/lib/third_party/urllib3/connectionpool.py", line 930, in _prepare_proxy
    conn.connect()
  File "/opt/homebrew/Caskroom/google-cloud-sdk/latest/google-cloud-sdk/lib/third_party/urllib3/connection.py", line 361, in connect
    self.sock = ssl_wrap_socket(
  File "/opt/homebrew/Caskroom/google-cloud-sdk/latest/google-cloud-sdk/lib/third_party/urllib3/util/ssl_.py", line 382, in ssl_wrap_socket
    return context.wrap_socket(sock, server_hostname=server_hostname)
  File "/opt/homebrew/Cellar/python@3.9/3.9.13_1/Frameworks/Python.framework/Versions/3.9/lib/python3.9/ssl.py", line 501, in wrap_socket
    return self.sslsocket_class._create(
  File "/opt/homebrew/Cellar/python@3.9/3.9.13_1/Frameworks/Python.framework/Versions/3.9/lib/python3.9/ssl.py", line 1041, in _create
    self.do_handshake()
  File "/opt/homebrew/Cellar/python@3.9/3.9.13_1/Frameworks/Python.framework/Versions/3.9/lib/python3.9/ssl.py", line 1310, in do_handshake
    self._sslobj.do_handshake()
ssl.SSLCertVerificationError: [SSL: CERTIFICATE_VERIFY_FAILED] certificate verify failed: unable to get local issuer certificate (_ssl.c:1129)

During handling of the above exception, another exception occurred:

Traceback (most recent call last):
  File "/opt/homebrew/Caskroom/google-cloud-sdk/latest/google-cloud-sdk/lib/third_party/requests/adapters.py", line 439, in send
    resp = conn.urlopen(
  File "/opt/homebrew/Caskroom/google-cloud-sdk/latest/google-cloud-sdk/lib/third_party/urllib3/connectionpool.py", line 724, in urlopen
    retries = retries.increment(
  File "/opt/homebrew/Caskroom/google-cloud-sdk/latest/google-cloud-sdk/lib/third_party/urllib3/util/retry.py", line 439, in increment
    raise MaxRetryError(_pool, url, error or ResponseError(cause))
urllib3.exceptions.MaxRetryError: HTTPSConnectionPool(host='oauth2.googleapis.com', port=443): Max retries exceeded with url: /token (Caused by SSLError(SSLCertVerificationError(1, '[SSL: CERTIFICATE_VERIFY_FAILED] certificate verify failed: unable to get local issuer certificate (_ssl.c:1129)')))

During handling of the above exception, another exception occurred:

Traceback (most recent call last):
  File "/opt/homebrew/Caskroom/google-cloud-sdk/latest/google-cloud-sdk/lib/third_party/google/auth/transport/requests.py", line 183, in __call__
    response = self.session.request(
  File "/opt/homebrew/Caskroom/google-cloud-sdk/latest/google-cloud-sdk/lib/googlecloudsdk/core/transport.py", line 251, in WrappedRequest
    response = orig_request(*modified_args, **modified_kwargs)
  File "/opt/homebrew/Caskroom/google-cloud-sdk/latest/google-cloud-sdk/lib/googlecloudsdk/core/requests.py", line 216, in WrappedRequest
    return orig_request_method(*args, **kwargs)
  File "/opt/homebrew/Caskroom/google-cloud-sdk/latest/google-cloud-sdk/lib/third_party/requests/sessions.py", line 533, in request
    resp = self.send(prep, **send_kwargs)
  File "/opt/homebrew/Caskroom/google-cloud-sdk/latest/google-cloud-sdk/lib/third_party/requests/sessions.py", line 646, in send
    r = adapter.send(request, **kwargs)
  File "/opt/homebrew/Caskroom/google-cloud-sdk/latest/google-cloud-sdk/lib/third_party/requests/adapters.py", line 514, in send
    raise SSLError(e, request=request)
requests.exceptions.SSLError: HTTPSConnectionPool(host='oauth2.googleapis.com', port=443): Max retries exceeded with url: /token (Caused by SSLError(SSLCertVerificationError(1, '[SSL: CERTIFICATE_VERIFY_FAILED] certificate verify failed: unable to get local issuer certificate (_ssl.c:1129)')))

The above exception was the direct cause of the following exception:

Traceback (most recent call last):
  File "/opt/homebrew/Caskroom/google-cloud-sdk/latest/google-cloud-sdk/lib/googlecloudsdk/command_lib/crash_handling.py", line 191, in Wrapper
    target_function(*args, **kwargs)
  File "/opt/homebrew/Caskroom/google-cloud-sdk/latest/google-cloud-sdk/lib/googlecloudsdk/gcloud_main.py", line 186, in main
    gcloud_cli.Execute()
  File "/opt/homebrew/Caskroom/google-cloud-sdk/latest/google-cloud-sdk/lib/googlecloudsdk/calliope/cli.py", line 1013, in Execute
    self._HandleAllErrors(exc, command_path_string, specified_arg_names)
  File "/opt/homebrew/Caskroom/google-cloud-sdk/latest/google-cloud-sdk/lib/googlecloudsdk/calliope/cli.py", line 1050, in _HandleAllErrors
    exceptions.HandleError(exc, command_path_string, self.__known_error_handler)
  File "/opt/homebrew/Caskroom/google-cloud-sdk/latest/google-cloud-sdk/lib/googlecloudsdk/calliope/exceptions.py", line 547, in HandleError
    core_exceptions.reraise(exc)
  File "/opt/homebrew/Caskroom/google-cloud-sdk/latest/google-cloud-sdk/lib/googlecloudsdk/core/exceptions.py", line 146, in reraise
    six.reraise(type(exc_value), exc_value, tb)
  File "/opt/homebrew/Caskroom/google-cloud-sdk/latest/google-cloud-sdk/lib/third_party/six/__init__.py", line 693, in reraise
    raise value
  File "/opt/homebrew/Caskroom/google-cloud-sdk/latest/google-cloud-sdk/lib/googlecloudsdk/calliope/cli.py", line 987, in Execute
    resources = calliope_command.Run(cli=self, args=args)
  File "/opt/homebrew/Caskroom/google-cloud-sdk/latest/google-cloud-sdk/lib/googlecloudsdk/calliope/backend.py", line 809, in Run
    resources = command_instance.Run(args)
  File "/opt/homebrew/Caskroom/google-cloud-sdk/latest/google-cloud-sdk/lib/surface/config/config_helper.py", line 99, in Run
    cred = store.Load(use_google_auth=True)
  File "/opt/homebrew/Caskroom/google-cloud-sdk/latest/google-cloud-sdk/lib/googlecloudsdk/core/credentials/store.py", line 565, in Load
    cred = _Load(
  File "/opt/homebrew/Caskroom/google-cloud-sdk/latest/google-cloud-sdk/lib/googlecloudsdk/core/credentials/store.py", line 728, in _Load
    RefreshIfAlmostExpire(cred)
  File "/opt/homebrew/Caskroom/google-cloud-sdk/latest/google-cloud-sdk/lib/googlecloudsdk/core/credentials/store.py", line 942, in RefreshIfAlmostExpire
    RefreshIfExpireWithinWindow(credentials, window=_CREDENTIALS_EXPIRY_WINDOW)
  File "/opt/homebrew/Caskroom/google-cloud-sdk/latest/google-cloud-sdk/lib/googlecloudsdk/core/credentials/store.py", line 938, in RefreshIfExpireWithinWindow
    Refresh(credentials)
  File "/opt/homebrew/Caskroom/google-cloud-sdk/latest/google-cloud-sdk/lib/googlecloudsdk/core/credentials/store.py", line 772, in Refresh
    _RefreshGoogleAuth(credentials, http_client, is_impersonated_credential,
  File "/opt/homebrew/Caskroom/google-cloud-sdk/latest/google-cloud-sdk/lib/googlecloudsdk/core/credentials/store.py", line 882, in _RefreshGoogleAuth
    credentials.refresh(request_client)
  File "/opt/homebrew/Caskroom/google-cloud-sdk/latest/google-cloud-sdk/lib/googlecloudsdk/core/credentials/creds.py", line 553, in _WrappedRefresh
    orig_refresh(request)
  File "/opt/homebrew/Caskroom/google-cloud-sdk/latest/google-cloud-sdk/lib/googlecloudsdk/core/credentials/google_auth_credentials.py", line 102, in refresh
    return self._Refresh(request)
  File "/opt/homebrew/Caskroom/google-cloud-sdk/latest/google-cloud-sdk/lib/googlecloudsdk/core/credentials/google_auth_credentials.py", line 129, in _Refresh
    access_token, refresh_token, expiry, grant_response = _RefreshGrant(
  File "/opt/homebrew/Caskroom/google-cloud-sdk/latest/google-cloud-sdk/lib/googlecloudsdk/core/credentials/google_auth_credentials.py", line 206, in _RefreshGrant
    response_data = _TokenEndpointRequestWithRetry(request, token_uri, body)
  File "/opt/homebrew/Caskroom/google-cloud-sdk/latest/google-cloud-sdk/lib/googlecloudsdk/core/util/retry.py", line 312, in DecoratedFunction
    exceptions.reraise(to_reraise[1], tb=to_reraise[2])
  File "/opt/homebrew/Caskroom/google-cloud-sdk/latest/google-cloud-sdk/lib/googlecloudsdk/core/exceptions.py", line 146, in reraise
    six.reraise(type(exc_value), exc_value, tb)
  File "/opt/homebrew/Caskroom/google-cloud-sdk/latest/google-cloud-sdk/lib/third_party/six/__init__.py", line 693, in reraise
    raise value
  File "/opt/homebrew/Caskroom/google-cloud-sdk/latest/google-cloud-sdk/lib/googlecloudsdk/core/util/retry.py", line 182, in TryFunc
    return func(*args, **kwargs), None
  File "/opt/homebrew/Caskroom/google-cloud-sdk/latest/google-cloud-sdk/lib/googlecloudsdk/core/credentials/google_auth_credentials.py", line 262, in _TokenEndpointRequestWithRetry
    response = request(method='POST', url=token_uri, headers=headers, body=body)
  File "/opt/homebrew/Caskroom/google-cloud-sdk/latest/google-cloud-sdk/lib/third_party/google/auth/transport/requests.py", line 189, in __call__
    six.raise_from(new_exc, caught_exc)
  File "<string>", line 3, in raise_from
google.auth.exceptions.TransportError: HTTPSConnectionPool(host='oauth2.googleapis.com', port=443): Max retries exceeded with url: /token (Caused by SSLError(SSLCertVerificationError(1, '[SSL: CERTIFICATE_VERIFY_FAILED] certificate verify failed: unable to get local issuer certificate (_ssl.c:1129)')))
2022-06-22 13:26:37,562 ERROR    root            gcloud crashed (TransportError): HTTPSConnectionPool(host='oauth2.googleapis.com', port=443): Max retries exceeded with url: /token (Caused by SSLError(SSLCertVerificationError(1, '[SSL: CERTIFICATE_VERIFY_FAILED] certificate verify failed: unable to get local issuer certificate (_ssl.c:1129)')))
2022-06-22 13:26:37,562 INFO     ___FILE_ONLY___ 
gcloud's default CA certificates failed to verify your connection, which can happen if you are behind a proxy or firewall.

2022-06-22 13:26:37,562 INFO     ___FILE_ONLY___ To use a custom CA certificates file, please run the following command:

2022-06-22 13:26:37,562 INFO     ___FILE_ONLY___   gcloud config set core/custom_ca_certs_file /path/to/ca_certs

2022-06-22 13:26:37,562 INFO     ___FILE_ONLY___ 
If you would like to report this issue, please run the following command:

2022-06-22 13:26:37,563 INFO     ___FILE_ONLY___   gcloud feedback

2022-06-22 13:26:37,563 INFO     ___FILE_ONLY___ 
To check gcloud for common problems, please run the following command:

2022-06-22 13:26:37,563 INFO     ___FILE_ONLY___   gcloud info --run-diagnostics

